[2025-01-31T00:41:04.416+0000] {local_task_job_runner.py:123} INFO - ::group::Pre task execution logs
[2025-01-31T00:41:04.532+0000] {taskinstance.py:2613} INFO - Dependencies all met for dep_context=non-requeueable deps ti=<TaskInstance: youtube_comments_etl_pipeline.extract_youtube_data scheduled__2025-01-30T00:00:00+00:00 [queued]>
[2025-01-31T00:41:04.536+0000] {taskinstance.py:2613} INFO - Dependencies all met for dep_context=requeueable deps ti=<TaskInstance: youtube_comments_etl_pipeline.extract_youtube_data scheduled__2025-01-30T00:00:00+00:00 [queued]>
[2025-01-31T00:41:04.537+0000] {taskinstance.py:2866} INFO - Starting attempt 1 of 1
[2025-01-31T00:41:04.543+0000] {taskinstance.py:2889} INFO - Executing <Task(_PythonDecoratedOperator): extract_youtube_data> on 2025-01-30 00:00:00+00:00
[2025-01-31T00:41:04.549+0000] {warnings.py:112} WARNING - /home/***/.local/lib/python3.12/site-packages/***/task/task_runner/standard_task_runner.py:70: DeprecationWarning: This process (pid=186) is multi-threaded, use of fork() may lead to deadlocks in the child.
  pid = os.fork()

[2025-01-31T00:41:04.551+0000] {standard_task_runner.py:104} INFO - Running: ['***', 'tasks', 'run', 'youtube_comments_etl_pipeline', 'extract_youtube_data', 'scheduled__2025-01-30T00:00:00+00:00', '--job-id', '416', '--raw', '--subdir', 'DAGS_FOLDER/youtube_comments_DAG.py', '--cfg-path', '/tmp/tmp_pe2c2t9']
[2025-01-31T00:41:04.552+0000] {standard_task_runner.py:72} INFO - Started process 189 to run task
[2025-01-31T00:41:04.552+0000] {standard_task_runner.py:105} INFO - Job 416: Subtask extract_youtube_data
[2025-01-31T00:41:04.580+0000] {task_command.py:467} INFO - Running <TaskInstance: youtube_comments_etl_pipeline.extract_youtube_data scheduled__2025-01-30T00:00:00+00:00 [running]> on host 6fb0b73b8178
[2025-01-31T00:41:04.639+0000] {taskinstance.py:3132} INFO - Exporting env vars: AIRFLOW_CTX_DAG_OWNER='***' AIRFLOW_CTX_DAG_ID='youtube_comments_etl_pipeline' AIRFLOW_CTX_TASK_ID='extract_youtube_data' AIRFLOW_CTX_EXECUTION_DATE='2025-01-30T00:00:00+00:00' AIRFLOW_CTX_TRY_NUMBER='1' AIRFLOW_CTX_DAG_RUN_ID='scheduled__2025-01-30T00:00:00+00:00'
[2025-01-31T00:41:04.642+0000] {logging_mixin.py:190} INFO - Task instance is in running state
[2025-01-31T00:41:04.642+0000] {logging_mixin.py:190} INFO -  Previous state of the Task instance: queued
[2025-01-31T00:41:04.643+0000] {logging_mixin.py:190} INFO - Current task name:extract_youtube_data state:running start_date:2025-01-31 00:41:04.533380+00:00
[2025-01-31T00:41:04.643+0000] {logging_mixin.py:190} INFO - Dag name:youtube_comments_etl_pipeline and current dag run status:running
[2025-01-31T00:41:04.643+0000] {taskinstance.py:731} INFO - ::endgroup::
[2025-01-31T00:41:04.649+0000] {__init__.py:49} INFO - file_cache is only supported with oauth2client<4.0.0
[2025-01-31T00:41:07.657+0000] {_metadata.py:142} WARNING - Compute Engine Metadata server unavailable on attempt 1 of 3. Reason: timed out
[2025-01-31T00:41:08.688+0000] {_metadata.py:142} WARNING - Compute Engine Metadata server unavailable on attempt 2 of 3. Reason: [Errno 111] Connection refused
[2025-01-31T00:41:10.777+0000] {_metadata.py:142} WARNING - Compute Engine Metadata server unavailable on attempt 3 of 3. Reason: [Errno 111] Connection refused
[2025-01-31T00:41:10.777+0000] {_default.py:340} WARNING - Authentication failed using Compute Engine authentication due to unavailable metadata server.
[2025-01-31T00:41:10.777+0000] {taskinstance.py:3311} ERROR - Task failed with exception
Traceback (most recent call last):
  File "/home/airflow/.local/lib/python3.12/site-packages/airflow/models/taskinstance.py", line 767, in _execute_task
    result = _execute_callable(context=context, **execute_callable_kwargs)
             ^^^^^^^^^^^^^^^^^^^^^^^^^^^^^^^^^^^^^^^^^^^^^^^^^^^^^^^^^^^^^
  File "/home/airflow/.local/lib/python3.12/site-packages/airflow/models/taskinstance.py", line 733, in _execute_callable
    return ExecutionCallableRunner(
           ^^^^^^^^^^^^^^^^^^^^^^^^
  File "/home/airflow/.local/lib/python3.12/site-packages/airflow/utils/operator_helpers.py", line 252, in run
    return self.func(*args, **kwargs)
           ^^^^^^^^^^^^^^^^^^^^^^^^^^
  File "/home/airflow/.local/lib/python3.12/site-packages/airflow/models/baseoperator.py", line 422, in wrapper
    return func(self, *args, **kwargs)
           ^^^^^^^^^^^^^^^^^^^^^^^^^^^
  File "/home/airflow/.local/lib/python3.12/site-packages/airflow/decorators/base.py", line 266, in execute
    return_value = super().execute(context)
                   ^^^^^^^^^^^^^^^^^^^^^^^^
  File "/home/airflow/.local/lib/python3.12/site-packages/airflow/models/baseoperator.py", line 422, in wrapper
    return func(self, *args, **kwargs)
           ^^^^^^^^^^^^^^^^^^^^^^^^^^^
  File "/home/airflow/.local/lib/python3.12/site-packages/airflow/operators/python.py", line 238, in execute
    return_value = self.execute_callable()
                   ^^^^^^^^^^^^^^^^^^^^^^^
  File "/home/airflow/.local/lib/python3.12/site-packages/airflow/operators/python.py", line 256, in execute_callable
    return runner.run(*self.op_args, **self.op_kwargs)
           ^^^^^^^^^^^^^^^^^^^^^^^^^^^^^^^^^^^^^^^^^^^
  File "/home/airflow/.local/lib/python3.12/site-packages/airflow/utils/operator_helpers.py", line 252, in run
    return self.func(*args, **kwargs)
           ^^^^^^^^^^^^^^^^^^^^^^^^^^
  File "/opt/airflow/dags/youtube_comments_DAG.py", line 43, in extract_youtube_data
    youtube = googleapiclient.discovery.build(
              ^^^^^^^^^^^^^^^^^^^^^^^^^^^^^^^^
  File "/home/airflow/.local/lib/python3.12/site-packages/googleapiclient/_helpers.py", line 130, in positional_wrapper
    return wrapped(*args, **kwargs)
           ^^^^^^^^^^^^^^^^^^^^^^^^
  File "/home/airflow/.local/lib/python3.12/site-packages/googleapiclient/discovery.py", line 315, in build
    service = build_from_document(
              ^^^^^^^^^^^^^^^^^^^^
  File "/home/airflow/.local/lib/python3.12/site-packages/googleapiclient/_helpers.py", line 130, in positional_wrapper
    return wrapped(*args, **kwargs)
           ^^^^^^^^^^^^^^^^^^^^^^^^
  File "/home/airflow/.local/lib/python3.12/site-packages/googleapiclient/discovery.py", line 616, in build_from_document
    credentials = _auth.default_credentials(
                  ^^^^^^^^^^^^^^^^^^^^^^^^^^
  File "/home/airflow/.local/lib/python3.12/site-packages/googleapiclient/_auth.py", line 57, in default_credentials
    credentials, _ = google.auth.default(
                     ^^^^^^^^^^^^^^^^^^^^
  File "/home/airflow/.local/lib/python3.12/site-packages/google/auth/_default.py", line 697, in default
    raise exceptions.DefaultCredentialsError(_CLOUD_SDK_MISSING_CREDENTIALS)
google.auth.exceptions.DefaultCredentialsError: Your default credentials were not found. To set up Application Default Credentials, see https://cloud.google.com/docs/authentication/external/set-up-adc for more information.
[2025-01-31T00:41:10.784+0000] {logging_mixin.py:190} INFO - Task instance in failure state
[2025-01-31T00:41:10.784+0000] {logging_mixin.py:190} INFO - Task start:2025-01-31 00:41:04.533380+00:00 end:2025-01-31 00:41:10.784425+00:00 duration:6.251045
[2025-01-31T00:41:10.785+0000] {logging_mixin.py:190} INFO - Task:<Task(_PythonDecoratedOperator): extract_youtube_data> dag:<DAG: youtube_comments_etl_pipeline> dagrun:<DagRun youtube_comments_etl_pipeline @ 2025-01-30 00:00:00+00:00: scheduled__2025-01-30T00:00:00+00:00, state:running, queued_at: 2025-01-31 00:41:00.773713+00:00. externally triggered: False>
[2025-01-31T00:41:10.785+0000] {logging_mixin.py:190} INFO - Failure caused by Your default credentials were not found. To set up Application Default Credentials, see https://cloud.google.com/docs/authentication/external/set-up-adc for more information.
[2025-01-31T00:41:10.785+0000] {taskinstance.py:1225} INFO - Marking task as FAILED. dag_id=youtube_comments_etl_pipeline, task_id=extract_youtube_data, run_id=scheduled__2025-01-30T00:00:00+00:00, execution_date=20250130T000000, start_date=20250131T004104, end_date=20250131T004110
[2025-01-31T00:41:10.791+0000] {taskinstance.py:340} INFO - ::group::Post task execution logs
[2025-01-31T00:41:10.791+0000] {standard_task_runner.py:124} ERROR - Failed to execute job 416 for task extract_youtube_data (Your default credentials were not found. To set up Application Default Credentials, see https://cloud.google.com/docs/authentication/external/set-up-adc for more information.; 189)
Traceback (most recent call last):
  File "/home/airflow/.local/lib/python3.12/site-packages/airflow/task/task_runner/standard_task_runner.py", line 117, in _start_by_fork
    ret = args.func(args, dag=self.dag)
          ^^^^^^^^^^^^^^^^^^^^^^^^^^^^^
  File "/home/airflow/.local/lib/python3.12/site-packages/airflow/cli/cli_config.py", line 49, in command
    return func(*args, **kwargs)
           ^^^^^^^^^^^^^^^^^^^^^
  File "/home/airflow/.local/lib/python3.12/site-packages/airflow/utils/cli.py", line 116, in wrapper
    return f(*args, **kwargs)
           ^^^^^^^^^^^^^^^^^^
  File "/home/airflow/.local/lib/python3.12/site-packages/airflow/cli/commands/task_command.py", line 483, in task_run
    task_return_code = _run_task_by_selected_method(args, _dag, ti)
                       ^^^^^^^^^^^^^^^^^^^^^^^^^^^^^^^^^^^^^^^^^^^^
  File "/home/airflow/.local/lib/python3.12/site-packages/airflow/cli/commands/task_command.py", line 256, in _run_task_by_selected_method
    return _run_raw_task(args, ti)
           ^^^^^^^^^^^^^^^^^^^^^^^
  File "/home/airflow/.local/lib/python3.12/site-packages/airflow/cli/commands/task_command.py", line 341, in _run_raw_task
    return ti._run_raw_task(
           ^^^^^^^^^^^^^^^^^
  File "/home/airflow/.local/lib/python3.12/site-packages/airflow/utils/session.py", line 97, in wrapper
    return func(*args, session=session, **kwargs)
           ^^^^^^^^^^^^^^^^^^^^^^^^^^^^^^^^^^^^^^
  File "/home/airflow/.local/lib/python3.12/site-packages/airflow/models/taskinstance.py", line 3005, in _run_raw_task
    return _run_raw_task(
           ^^^^^^^^^^^^^^
  File "/home/airflow/.local/lib/python3.12/site-packages/airflow/models/taskinstance.py", line 273, in _run_raw_task
    TaskInstance._execute_task_with_callbacks(
  File "/home/airflow/.local/lib/python3.12/site-packages/airflow/models/taskinstance.py", line 3159, in _execute_task_with_callbacks
    result = self._execute_task(context, task_orig)
             ^^^^^^^^^^^^^^^^^^^^^^^^^^^^^^^^^^^^^^
  File "/home/airflow/.local/lib/python3.12/site-packages/airflow/models/taskinstance.py", line 3183, in _execute_task
    return _execute_task(self, context, task_orig)
           ^^^^^^^^^^^^^^^^^^^^^^^^^^^^^^^^^^^^^^^
  File "/home/airflow/.local/lib/python3.12/site-packages/airflow/models/taskinstance.py", line 767, in _execute_task
    result = _execute_callable(context=context, **execute_callable_kwargs)
             ^^^^^^^^^^^^^^^^^^^^^^^^^^^^^^^^^^^^^^^^^^^^^^^^^^^^^^^^^^^^^
  File "/home/airflow/.local/lib/python3.12/site-packages/airflow/models/taskinstance.py", line 733, in _execute_callable
    return ExecutionCallableRunner(
           ^^^^^^^^^^^^^^^^^^^^^^^^
  File "/home/airflow/.local/lib/python3.12/site-packages/airflow/utils/operator_helpers.py", line 252, in run
    return self.func(*args, **kwargs)
           ^^^^^^^^^^^^^^^^^^^^^^^^^^
  File "/home/airflow/.local/lib/python3.12/site-packages/airflow/models/baseoperator.py", line 422, in wrapper
    return func(self, *args, **kwargs)
           ^^^^^^^^^^^^^^^^^^^^^^^^^^^
  File "/home/airflow/.local/lib/python3.12/site-packages/airflow/decorators/base.py", line 266, in execute
    return_value = super().execute(context)
                   ^^^^^^^^^^^^^^^^^^^^^^^^
  File "/home/airflow/.local/lib/python3.12/site-packages/airflow/models/baseoperator.py", line 422, in wrapper
    return func(self, *args, **kwargs)
           ^^^^^^^^^^^^^^^^^^^^^^^^^^^
  File "/home/airflow/.local/lib/python3.12/site-packages/airflow/operators/python.py", line 238, in execute
    return_value = self.execute_callable()
                   ^^^^^^^^^^^^^^^^^^^^^^^
  File "/home/airflow/.local/lib/python3.12/site-packages/airflow/operators/python.py", line 256, in execute_callable
    return runner.run(*self.op_args, **self.op_kwargs)
           ^^^^^^^^^^^^^^^^^^^^^^^^^^^^^^^^^^^^^^^^^^^
  File "/home/airflow/.local/lib/python3.12/site-packages/airflow/utils/operator_helpers.py", line 252, in run
    return self.func(*args, **kwargs)
           ^^^^^^^^^^^^^^^^^^^^^^^^^^
  File "/opt/airflow/dags/youtube_comments_DAG.py", line 43, in extract_youtube_data
    youtube = googleapiclient.discovery.build(
              ^^^^^^^^^^^^^^^^^^^^^^^^^^^^^^^^
  File "/home/airflow/.local/lib/python3.12/site-packages/googleapiclient/_helpers.py", line 130, in positional_wrapper
    return wrapped(*args, **kwargs)
           ^^^^^^^^^^^^^^^^^^^^^^^^
  File "/home/airflow/.local/lib/python3.12/site-packages/googleapiclient/discovery.py", line 315, in build
    service = build_from_document(
              ^^^^^^^^^^^^^^^^^^^^
  File "/home/airflow/.local/lib/python3.12/site-packages/googleapiclient/_helpers.py", line 130, in positional_wrapper
    return wrapped(*args, **kwargs)
           ^^^^^^^^^^^^^^^^^^^^^^^^
  File "/home/airflow/.local/lib/python3.12/site-packages/googleapiclient/discovery.py", line 616, in build_from_document
    credentials = _auth.default_credentials(
                  ^^^^^^^^^^^^^^^^^^^^^^^^^^
  File "/home/airflow/.local/lib/python3.12/site-packages/googleapiclient/_auth.py", line 57, in default_credentials
    credentials, _ = google.auth.default(
                     ^^^^^^^^^^^^^^^^^^^^
  File "/home/airflow/.local/lib/python3.12/site-packages/google/auth/_default.py", line 697, in default
    raise exceptions.DefaultCredentialsError(_CLOUD_SDK_MISSING_CREDENTIALS)
google.auth.exceptions.DefaultCredentialsError: Your default credentials were not found. To set up Application Default Credentials, see https://cloud.google.com/docs/authentication/external/set-up-adc for more information.
[2025-01-31T00:41:10.826+0000] {local_task_job_runner.py:266} INFO - Task exited with return code 1
[2025-01-31T00:41:10.835+0000] {taskinstance.py:3895} INFO - 0 downstream tasks scheduled from follow-on schedule check
[2025-01-31T00:41:10.836+0000] {local_task_job_runner.py:245} INFO - ::endgroup::
