[2025-01-29T22:47:27.704+0000] {local_task_job_runner.py:123} INFO - ::group::Pre task execution logs
[2025-01-29T22:47:27.711+0000] {taskinstance.py:2613} INFO - Dependencies all met for dep_context=non-requeueable deps ti=<TaskInstance: weather_etl_pipeline.load_weather_data manual__2025-01-29T22:47:20.527791+00:00 [queued]>
[2025-01-29T22:47:27.715+0000] {taskinstance.py:2613} INFO - Dependencies all met for dep_context=requeueable deps ti=<TaskInstance: weather_etl_pipeline.load_weather_data manual__2025-01-29T22:47:20.527791+00:00 [queued]>
[2025-01-29T22:47:27.715+0000] {taskinstance.py:2866} INFO - Starting attempt 1 of 1
[2025-01-29T22:47:27.722+0000] {taskinstance.py:2889} INFO - Executing <Task(_PythonDecoratedOperator): load_weather_data> on 2025-01-29 22:47:20.527791+00:00
[2025-01-29T22:47:27.731+0000] {warnings.py:112} WARNING - /home/***/.local/lib/python3.12/site-packages/***/task/task_runner/standard_task_runner.py:70: DeprecationWarning: This process (pid=151) is multi-threaded, use of fork() may lead to deadlocks in the child.
  pid = os.fork()

[2025-01-29T22:47:27.731+0000] {standard_task_runner.py:72} INFO - Started process 154 to run task
[2025-01-29T22:47:27.732+0000] {standard_task_runner.py:104} INFO - Running: ['***', 'tasks', 'run', 'weather_etl_pipeline', 'load_weather_data', 'manual__2025-01-29T22:47:20.527791+00:00', '--job-id', '400', '--raw', '--subdir', 'DAGS_FOLDER/app.py', '--cfg-path', '/tmp/tmpja4gkxjh']
[2025-01-29T22:47:27.733+0000] {standard_task_runner.py:105} INFO - Job 400: Subtask load_weather_data
[2025-01-29T22:47:27.750+0000] {task_command.py:467} INFO - Running <TaskInstance: weather_etl_pipeline.load_weather_data manual__2025-01-29T22:47:20.527791+00:00 [running]> on host 10ad9b47e333
[2025-01-29T22:47:27.786+0000] {taskinstance.py:3132} INFO - Exporting env vars: AIRFLOW_CTX_DAG_OWNER='***' AIRFLOW_CTX_DAG_ID='weather_etl_pipeline' AIRFLOW_CTX_TASK_ID='load_weather_data' AIRFLOW_CTX_EXECUTION_DATE='2025-01-29T22:47:20.527791+00:00' AIRFLOW_CTX_TRY_NUMBER='1' AIRFLOW_CTX_DAG_RUN_ID='manual__2025-01-29T22:47:20.527791+00:00'
[2025-01-29T22:47:27.787+0000] {logging_mixin.py:190} INFO - Task instance is in running state
[2025-01-29T22:47:27.787+0000] {logging_mixin.py:190} INFO -  Previous state of the Task instance: queued
[2025-01-29T22:47:27.788+0000] {logging_mixin.py:190} INFO - Current task name:load_weather_data state:running start_date:2025-01-29 22:47:27.712212+00:00
[2025-01-29T22:47:27.788+0000] {logging_mixin.py:190} INFO - Dag name:weather_etl_pipeline and current dag run status:running
[2025-01-29T22:47:27.788+0000] {taskinstance.py:731} INFO - ::endgroup::
[2025-01-29T22:47:27.792+0000] {base.py:84} INFO - Retrieving connection 'books_connection'
[2025-01-29T22:47:27.799+0000] {taskinstance.py:3311} ERROR - Task failed with exception
Traceback (most recent call last):
  File "/home/airflow/.local/lib/python3.12/site-packages/airflow/models/taskinstance.py", line 767, in _execute_task
    result = _execute_callable(context=context, **execute_callable_kwargs)
             ^^^^^^^^^^^^^^^^^^^^^^^^^^^^^^^^^^^^^^^^^^^^^^^^^^^^^^^^^^^^^
  File "/home/airflow/.local/lib/python3.12/site-packages/airflow/models/taskinstance.py", line 733, in _execute_callable
    return ExecutionCallableRunner(
           ^^^^^^^^^^^^^^^^^^^^^^^^
  File "/home/airflow/.local/lib/python3.12/site-packages/airflow/utils/operator_helpers.py", line 252, in run
    return self.func(*args, **kwargs)
           ^^^^^^^^^^^^^^^^^^^^^^^^^^
  File "/home/airflow/.local/lib/python3.12/site-packages/airflow/models/baseoperator.py", line 422, in wrapper
    return func(self, *args, **kwargs)
           ^^^^^^^^^^^^^^^^^^^^^^^^^^^
  File "/home/airflow/.local/lib/python3.12/site-packages/airflow/decorators/base.py", line 266, in execute
    return_value = super().execute(context)
                   ^^^^^^^^^^^^^^^^^^^^^^^^
  File "/home/airflow/.local/lib/python3.12/site-packages/airflow/models/baseoperator.py", line 422, in wrapper
    return func(self, *args, **kwargs)
           ^^^^^^^^^^^^^^^^^^^^^^^^^^^
  File "/home/airflow/.local/lib/python3.12/site-packages/airflow/operators/python.py", line 238, in execute
    return_value = self.execute_callable()
                   ^^^^^^^^^^^^^^^^^^^^^^^
  File "/home/airflow/.local/lib/python3.12/site-packages/airflow/operators/python.py", line 256, in execute_callable
    return runner.run(*self.op_args, **self.op_kwargs)
           ^^^^^^^^^^^^^^^^^^^^^^^^^^^^^^^^^^^^^^^^^^^
  File "/home/airflow/.local/lib/python3.12/site-packages/airflow/utils/operator_helpers.py", line 252, in run
    return self.func(*args, **kwargs)
           ^^^^^^^^^^^^^^^^^^^^^^^^^^
  File "/opt/airflow/dags/app.py", line 85, in load_weather_data
    cursor.execute("""
psycopg2.errors.UniqueViolation: duplicate key value violates unique constraint "pg_type_typname_nsp_index"
DETAIL:  Key (typname, typnamespace)=(weather_data, 2200) already exists.

[2025-01-29T22:47:27.803+0000] {logging_mixin.py:190} INFO - Task instance in failure state
[2025-01-29T22:47:27.803+0000] {logging_mixin.py:190} INFO - Task start:2025-01-29 22:47:27.712212+00:00 end:2025-01-29 22:47:27.803176+00:00 duration:0.090964
[2025-01-29T22:47:27.803+0000] {logging_mixin.py:190} INFO - Task:<Task(_PythonDecoratedOperator): load_weather_data> dag:<DAG: weather_etl_pipeline> dagrun:<DagRun weather_etl_pipeline @ 2025-01-29 22:47:20.527791+00:00: manual__2025-01-29T22:47:20.527791+00:00, state:running, queued_at: 2025-01-29 22:47:20.554678+00:00. externally triggered: True>
[2025-01-29T22:47:27.803+0000] {logging_mixin.py:190} INFO - Failure caused by duplicate key value violates unique constraint "pg_type_typname_nsp_index"
DETAIL:  Key (typname, typnamespace)=(weather_data, 2200) already exists.
[2025-01-29T22:47:27.803+0000] {taskinstance.py:1225} INFO - Marking task as FAILED. dag_id=weather_etl_pipeline, task_id=load_weather_data, run_id=manual__2025-01-29T22:47:20.527791+00:00, execution_date=20250129T224720, start_date=20250129T224727, end_date=20250129T224727
[2025-01-29T22:47:27.807+0000] {taskinstance.py:340} INFO - ::group::Post task execution logs
[2025-01-29T22:47:27.808+0000] {standard_task_runner.py:124} ERROR - Failed to execute job 400 for task load_weather_data (duplicate key value violates unique constraint "pg_type_typname_nsp_index"
DETAIL:  Key (typname, typnamespace)=(weather_data, 2200) already exists.
; 154)
Traceback (most recent call last):
  File "/home/airflow/.local/lib/python3.12/site-packages/airflow/task/task_runner/standard_task_runner.py", line 117, in _start_by_fork
    ret = args.func(args, dag=self.dag)
          ^^^^^^^^^^^^^^^^^^^^^^^^^^^^^
  File "/home/airflow/.local/lib/python3.12/site-packages/airflow/cli/cli_config.py", line 49, in command
    return func(*args, **kwargs)
           ^^^^^^^^^^^^^^^^^^^^^
  File "/home/airflow/.local/lib/python3.12/site-packages/airflow/utils/cli.py", line 116, in wrapper
    return f(*args, **kwargs)
           ^^^^^^^^^^^^^^^^^^
  File "/home/airflow/.local/lib/python3.12/site-packages/airflow/cli/commands/task_command.py", line 483, in task_run
    task_return_code = _run_task_by_selected_method(args, _dag, ti)
                       ^^^^^^^^^^^^^^^^^^^^^^^^^^^^^^^^^^^^^^^^^^^^
  File "/home/airflow/.local/lib/python3.12/site-packages/airflow/cli/commands/task_command.py", line 256, in _run_task_by_selected_method
    return _run_raw_task(args, ti)
           ^^^^^^^^^^^^^^^^^^^^^^^
  File "/home/airflow/.local/lib/python3.12/site-packages/airflow/cli/commands/task_command.py", line 341, in _run_raw_task
    return ti._run_raw_task(
           ^^^^^^^^^^^^^^^^^
  File "/home/airflow/.local/lib/python3.12/site-packages/airflow/utils/session.py", line 97, in wrapper
    return func(*args, session=session, **kwargs)
           ^^^^^^^^^^^^^^^^^^^^^^^^^^^^^^^^^^^^^^
  File "/home/airflow/.local/lib/python3.12/site-packages/airflow/models/taskinstance.py", line 3005, in _run_raw_task
    return _run_raw_task(
           ^^^^^^^^^^^^^^
  File "/home/airflow/.local/lib/python3.12/site-packages/airflow/models/taskinstance.py", line 273, in _run_raw_task
    TaskInstance._execute_task_with_callbacks(
  File "/home/airflow/.local/lib/python3.12/site-packages/airflow/models/taskinstance.py", line 3159, in _execute_task_with_callbacks
    result = self._execute_task(context, task_orig)
             ^^^^^^^^^^^^^^^^^^^^^^^^^^^^^^^^^^^^^^
  File "/home/airflow/.local/lib/python3.12/site-packages/airflow/models/taskinstance.py", line 3183, in _execute_task
    return _execute_task(self, context, task_orig)
           ^^^^^^^^^^^^^^^^^^^^^^^^^^^^^^^^^^^^^^^
  File "/home/airflow/.local/lib/python3.12/site-packages/airflow/models/taskinstance.py", line 767, in _execute_task
    result = _execute_callable(context=context, **execute_callable_kwargs)
             ^^^^^^^^^^^^^^^^^^^^^^^^^^^^^^^^^^^^^^^^^^^^^^^^^^^^^^^^^^^^^
  File "/home/airflow/.local/lib/python3.12/site-packages/airflow/models/taskinstance.py", line 733, in _execute_callable
    return ExecutionCallableRunner(
           ^^^^^^^^^^^^^^^^^^^^^^^^
  File "/home/airflow/.local/lib/python3.12/site-packages/airflow/utils/operator_helpers.py", line 252, in run
    return self.func(*args, **kwargs)
           ^^^^^^^^^^^^^^^^^^^^^^^^^^
  File "/home/airflow/.local/lib/python3.12/site-packages/airflow/models/baseoperator.py", line 422, in wrapper
    return func(self, *args, **kwargs)
           ^^^^^^^^^^^^^^^^^^^^^^^^^^^
  File "/home/airflow/.local/lib/python3.12/site-packages/airflow/decorators/base.py", line 266, in execute
    return_value = super().execute(context)
                   ^^^^^^^^^^^^^^^^^^^^^^^^
  File "/home/airflow/.local/lib/python3.12/site-packages/airflow/models/baseoperator.py", line 422, in wrapper
    return func(self, *args, **kwargs)
           ^^^^^^^^^^^^^^^^^^^^^^^^^^^
  File "/home/airflow/.local/lib/python3.12/site-packages/airflow/operators/python.py", line 238, in execute
    return_value = self.execute_callable()
                   ^^^^^^^^^^^^^^^^^^^^^^^
  File "/home/airflow/.local/lib/python3.12/site-packages/airflow/operators/python.py", line 256, in execute_callable
    return runner.run(*self.op_args, **self.op_kwargs)
           ^^^^^^^^^^^^^^^^^^^^^^^^^^^^^^^^^^^^^^^^^^^
  File "/home/airflow/.local/lib/python3.12/site-packages/airflow/utils/operator_helpers.py", line 252, in run
    return self.func(*args, **kwargs)
           ^^^^^^^^^^^^^^^^^^^^^^^^^^
  File "/opt/airflow/dags/app.py", line 85, in load_weather_data
    cursor.execute("""
psycopg2.errors.UniqueViolation: duplicate key value violates unique constraint "pg_type_typname_nsp_index"
DETAIL:  Key (typname, typnamespace)=(weather_data, 2200) already exists.

[2025-01-29T22:47:27.830+0000] {local_task_job_runner.py:266} INFO - Task exited with return code 1
[2025-01-29T22:47:27.838+0000] {taskinstance.py:3895} INFO - 0 downstream tasks scheduled from follow-on schedule check
[2025-01-29T22:47:27.839+0000] {local_task_job_runner.py:245} INFO - ::endgroup::
